2025-09-30 21:22:48,255 - ERROR - An exception occurred: 2003 (HY000): Can't connect to MySQL server on 'localhost:3306' (10061)
Traceback (most recent call last):
  File "C:\Users\adria\Downloads\projeto\.venv\Lib\site-packages\mysql\connector\connection_cext.py", line 354, in _open_connection
    self._cmysql.connect(**cnx_kwargs)
    ~~~~~~~~~~~~~~~~~~~~^^^^^^^^^^^^^^
_mysql_connector.MySQLInterfaceError: Can't connect to MySQL server on 'localhost:3306' (10061)

The above exception was the direct cause of the following exception:

Traceback (most recent call last):
  File "C:\Users\adria\Downloads\projeto\database.py", line 17, in connect
    self.connection = mysql.connector.connect(
                      ~~~~~~~~~~~~~~~~~~~~~~~^
        host=self.host,
        ^^^^^^^^^^^^^^^
    ...<2 lines>...
        database=self.database
        ^^^^^^^^^^^^^^^^^^^^^^
    )
    ^
  File "C:\Users\adria\Downloads\projeto\.venv\Lib\site-packages\mysql\connector\pooling.py", line 322, in connect
    return CMySQLConnection(*args, **kwargs)
  File "C:\Users\adria\Downloads\projeto\.venv\Lib\site-packages\mysql\connector\connection_cext.py", line 142, in __init__
    self.connect(**kwargs)
    ~~~~~~~~~~~~^^^^^^^^^^
  File "C:\Users\adria\Downloads\projeto\.venv\Lib\site-packages\mysql\connector\abstracts.py", line 1604, in connect
    self._open_connection()
    ~~~~~~~~~~~~~~~~~~~~~^^
  File "C:\Users\adria\Downloads\projeto\.venv\Lib\site-packages\mysql\connector\connection_cext.py", line 360, in _open_connection
    raise get_mysql_exception(
        err.errno, msg=err.msg, sqlstate=err.sqlstate
    ) from err
mysql.connector.errors.DatabaseError: 2003 (HY000): Can't connect to MySQL server on 'localhost:3306' (10061)
2025-09-30 21:41:41,384 - ERROR - An exception occurred: 1045 (28000): Access denied for user 'root'@'localhost' (using password: YES)
Traceback (most recent call last):
  File "C:\Users\adria\Downloads\projeto\.venv\Lib\site-packages\mysql\connector\connection_cext.py", line 354, in _open_connection
    self._cmysql.connect(**cnx_kwargs)
    ~~~~~~~~~~~~~~~~~~~~^^^^^^^^^^^^^^
_mysql_connector.MySQLInterfaceError: Access denied for user 'root'@'localhost' (using password: YES)

The above exception was the direct cause of the following exception:

Traceback (most recent call last):
  File "C:\Users\adria\Downloads\projeto\database.py", line 17, in connect
    self.connection = mysql.connector.connect(
                      ~~~~~~~~~~~~~~~~~~~~~~~^
        host=self.host,
        ^^^^^^^^^^^^^^^
    ...<2 lines>...
        database=self.database
        ^^^^^^^^^^^^^^^^^^^^^^
    )
    ^
  File "C:\Users\adria\Downloads\projeto\.venv\Lib\site-packages\mysql\connector\pooling.py", line 322, in connect
    return CMySQLConnection(*args, **kwargs)
  File "C:\Users\adria\Downloads\projeto\.venv\Lib\site-packages\mysql\connector\connection_cext.py", line 142, in __init__
    self.connect(**kwargs)
    ~~~~~~~~~~~~^^^^^^^^^^
  File "C:\Users\adria\Downloads\projeto\.venv\Lib\site-packages\mysql\connector\abstracts.py", line 1604, in connect
    self._open_connection()
    ~~~~~~~~~~~~~~~~~~~~~^^
  File "C:\Users\adria\Downloads\projeto\.venv\Lib\site-packages\mysql\connector\connection_cext.py", line 360, in _open_connection
    raise get_mysql_exception(
        err.errno, msg=err.msg, sqlstate=err.sqlstate
    ) from err
mysql.connector.errors.ProgrammingError: 1045 (28000): Access denied for user 'root'@'localhost' (using password: YES)
2025-09-30 21:45:13,519 - ERROR - An exception occurred: 1146 (42S02): Table 'sales_system.users' doesn't exist
Traceback (most recent call last):
  File "C:\Users\adria\Downloads\projeto\.venv\Lib\site-packages\mysql\connector\connection_cext.py", line 772, in cmd_query
    self._cmysql.query(
    ~~~~~~~~~~~~~~~~~~^
        query,
        ^^^^^^
    ...<3 lines>...
        query_attrs=self.query_attrs,
        ^^^^^^^^^^^^^^^^^^^^^^^^^^^^^
    )
    ^
_mysql_connector.MySQLInterfaceError: Table 'sales_system.users' doesn't exist

The above exception was the direct cause of the following exception:

Traceback (most recent call last):
  File "c:\Users\adria\Downloads\projeto\database.py", line 59, in fetch_one
    self.cursor.execute(query, params or ())
    ~~~~~~~~~~~~~~~~~~~^^^^^^^^^^^^^^^^^^^^^
  File "C:\Users\adria\Downloads\projeto\.venv\Lib\site-packages\mysql\connector\cursor_cext.py", line 353, in execute
    self._connection.cmd_query(
    ~~~~~~~~~~~~~~~~~~~~~~~~~~^
        self._stmt_partition["mappable_stmt"],
        ^^^^^^^^^^^^^^^^^^^^^^^^^^^^^^^^^^^^^^
    ...<2 lines>...
        raw_as_string=self._raw_as_string,
        ^^^^^^^^^^^^^^^^^^^^^^^^^^^^^^^^^^
    )
    ^
  File "C:\Users\adria\Downloads\projeto\.venv\Lib\site-packages\mysql\connector\opentelemetry\context_propagation.py", line 97, in wrapper
    return method(cnx, *args, **kwargs)
  File "C:\Users\adria\Downloads\projeto\.venv\Lib\site-packages\mysql\connector\connection_cext.py", line 781, in cmd_query
    raise get_mysql_exception(
        err.errno, msg=err.msg, sqlstate=err.sqlstate
    ) from err
mysql.connector.errors.ProgrammingError: 1146 (42S02): Table 'sales_system.users' doesn't exist
2025-09-30 21:45:31,799 - ERROR - An exception occurred: 1146 (42S02): Table 'sales_system.users' doesn't exist
Traceback (most recent call last):
  File "C:\Users\adria\Downloads\projeto\.venv\Lib\site-packages\mysql\connector\connection_cext.py", line 772, in cmd_query
    self._cmysql.query(
    ~~~~~~~~~~~~~~~~~~^
        query,
        ^^^^^^
    ...<3 lines>...
        query_attrs=self.query_attrs,
        ^^^^^^^^^^^^^^^^^^^^^^^^^^^^^
    )
    ^
_mysql_connector.MySQLInterfaceError: Table 'sales_system.users' doesn't exist

The above exception was the direct cause of the following exception:

Traceback (most recent call last):
  File "c:\Users\adria\Downloads\projeto\database.py", line 59, in fetch_one
    self.cursor.execute(query, params or ())
    ~~~~~~~~~~~~~~~~~~~^^^^^^^^^^^^^^^^^^^^^
  File "C:\Users\adria\Downloads\projeto\.venv\Lib\site-packages\mysql\connector\cursor_cext.py", line 353, in execute
    self._connection.cmd_query(
    ~~~~~~~~~~~~~~~~~~~~~~~~~~^
        self._stmt_partition["mappable_stmt"],
        ^^^^^^^^^^^^^^^^^^^^^^^^^^^^^^^^^^^^^^
    ...<2 lines>...
        raw_as_string=self._raw_as_string,
        ^^^^^^^^^^^^^^^^^^^^^^^^^^^^^^^^^^
    )
    ^
  File "C:\Users\adria\Downloads\projeto\.venv\Lib\site-packages\mysql\connector\opentelemetry\context_propagation.py", line 97, in wrapper
    return method(cnx, *args, **kwargs)
  File "C:\Users\adria\Downloads\projeto\.venv\Lib\site-packages\mysql\connector\connection_cext.py", line 781, in cmd_query
    raise get_mysql_exception(
        err.errno, msg=err.msg, sqlstate=err.sqlstate
    ) from err
mysql.connector.errors.ProgrammingError: 1146 (42S02): Table 'sales_system.users' doesn't exist
2025-09-30 21:46:04,272 - ERROR - An exception occurred: 1146 (42S02): Table 'sales_system.users' doesn't exist
Traceback (most recent call last):
  File "C:\Users\adria\Downloads\projeto\.venv\Lib\site-packages\mysql\connector\connection_cext.py", line 772, in cmd_query
    self._cmysql.query(
    ~~~~~~~~~~~~~~~~~~^
        query,
        ^^^^^^
    ...<3 lines>...
        query_attrs=self.query_attrs,
        ^^^^^^^^^^^^^^^^^^^^^^^^^^^^^
    )
    ^
_mysql_connector.MySQLInterfaceError: Table 'sales_system.users' doesn't exist

The above exception was the direct cause of the following exception:

Traceback (most recent call last):
  File "C:\Users\adria\Downloads\projeto\database.py", line 59, in fetch_one
    self.cursor.execute(query, params or ())
    ~~~~~~~~~~~~~~~~~~~^^^^^^^^^^^^^^^^^^^^^
  File "C:\Users\adria\Downloads\projeto\.venv\Lib\site-packages\mysql\connector\cursor_cext.py", line 353, in execute
    self._connection.cmd_query(
    ~~~~~~~~~~~~~~~~~~~~~~~~~~^
        self._stmt_partition["mappable_stmt"],
        ^^^^^^^^^^^^^^^^^^^^^^^^^^^^^^^^^^^^^^
    ...<2 lines>...
        raw_as_string=self._raw_as_string,
        ^^^^^^^^^^^^^^^^^^^^^^^^^^^^^^^^^^
    )
    ^
  File "C:\Users\adria\Downloads\projeto\.venv\Lib\site-packages\mysql\connector\opentelemetry\context_propagation.py", line 97, in wrapper
    return method(cnx, *args, **kwargs)
  File "C:\Users\adria\Downloads\projeto\.venv\Lib\site-packages\mysql\connector\connection_cext.py", line 781, in cmd_query
    raise get_mysql_exception(
        err.errno, msg=err.msg, sqlstate=err.sqlstate
    ) from err
mysql.connector.errors.ProgrammingError: 1146 (42S02): Table 'sales_system.users' doesn't exist
2025-09-30 21:46:06,871 - ERROR - An exception occurred: 1146 (42S02): Table 'sales_system.users' doesn't exist
Traceback (most recent call last):
  File "C:\Users\adria\Downloads\projeto\.venv\Lib\site-packages\mysql\connector\connection_cext.py", line 772, in cmd_query
    self._cmysql.query(
    ~~~~~~~~~~~~~~~~~~^
        query,
        ^^^^^^
    ...<3 lines>...
        query_attrs=self.query_attrs,
        ^^^^^^^^^^^^^^^^^^^^^^^^^^^^^
    )
    ^
_mysql_connector.MySQLInterfaceError: Table 'sales_system.users' doesn't exist

The above exception was the direct cause of the following exception:

Traceback (most recent call last):
  File "C:\Users\adria\Downloads\projeto\database.py", line 59, in fetch_one
    self.cursor.execute(query, params or ())
    ~~~~~~~~~~~~~~~~~~~^^^^^^^^^^^^^^^^^^^^^
  File "C:\Users\adria\Downloads\projeto\.venv\Lib\site-packages\mysql\connector\cursor_cext.py", line 353, in execute
    self._connection.cmd_query(
    ~~~~~~~~~~~~~~~~~~~~~~~~~~^
        self._stmt_partition["mappable_stmt"],
        ^^^^^^^^^^^^^^^^^^^^^^^^^^^^^^^^^^^^^^
    ...<2 lines>...
        raw_as_string=self._raw_as_string,
        ^^^^^^^^^^^^^^^^^^^^^^^^^^^^^^^^^^
    )
    ^
  File "C:\Users\adria\Downloads\projeto\.venv\Lib\site-packages\mysql\connector\opentelemetry\context_propagation.py", line 97, in wrapper
    return method(cnx, *args, **kwargs)
  File "C:\Users\adria\Downloads\projeto\.venv\Lib\site-packages\mysql\connector\connection_cext.py", line 781, in cmd_query
    raise get_mysql_exception(
        err.errno, msg=err.msg, sqlstate=err.sqlstate
    ) from err
mysql.connector.errors.ProgrammingError: 1146 (42S02): Table 'sales_system.users' doesn't exist
